Workbook

Sheet Sheet1
A1: Timestamp | B1: Title | C1: Difficulty | D1: Option#1 | E1: Option#2 | F1: Option#3 | G1: Comment
A2: EPOLIS_RAW | B2: A | C2: A | D2: FLIP | E2: MIRROR | F2: OFF | H2: EPOLIS_RAW
A3: EPOLIS_RAW | B3: AA | C3: A | D3: FLIP | E3: MIRROR | F3: OFF | H3: EPOLIS_RAW
A4: EPOLIS_RAW | B4: AA -rebuild- | C4: A | D4: OFF | E4: MIRROR | F4: OFF | H4: EPOLIS_RAW
A5: EPOLIS_RAW | B5: ABSOLUTE EVIL | C5: A | D5: OFF | E5: MIRROR | F5: OFF | H5: EPOLIS_RAW
A6: EPOLIS_RAW | B6: ACTØ | C6: A | D6: OFF | E6: MIRROR | F6: OFF | H6: EPOLIS_RAW
A7: EPOLIS_RAW | B7: Adularia | C7: A | D7: OFF | E7: MIRROR | F7: OFF | H7: EPOLIS_RAW
A8: EPOLIS_RAW | B8: Afterimage d'automne | C8: A | D8: OFF | E8: MIRROR | F8: OFF | H8: EPOLIS_RAW
A9: EPOLIS_RAW | B9: Aftermath | C9: A | D9: OFF | E9: MIRROR | F9: OFF | H9: EPOLIS_RAW
A10: EPOLIS_RAW | B10: AIR RAID FROM THA UNDAGROUND | C10: L | D10: OFF | E10: MIRROR | F10: OFF | H10: EPOLIS_RAW
A11: EPOLIS_RAW | B11: AKASHIC BREAK | C11: A | D11: OFF | E11: MIRROR | F11: OFF | H11: EPOLIS_RAW
A12: EPOLIS_RAW | B12: Almagest | C12: A | D12: OFF | E12: MIRROR | F12: OFF | H12: EPOLIS_RAW
A13: EPOLIS_RAW | B13: ALTERNATOR | C13: A | D13: OFF | E13: MIRROR | F13: OFF | H13: EPOLIS_RAW
... A485: EPOLIS_RAW | B485: 24h Endurance Race | C485: A | D485: OFF | E485: MIRROR | F485: OFF | H485: EPOLIS_RAW
A486: EPOLIS_RAW | B486: 255 | C486: A | D486: OFF | E486: MIRROR | F486: OFF | H486: EPOLIS_RAW
A487: EPOLIS_RAW | B487: 3y3s | C487: A | D487: OFF | E487: MIRROR | F487: OFF | H487: EPOLIS_RAW
A488: EPOLIS_RAW | B488: [ ]DENTITY | C488: A | D488: OFF | E488: MIRROR | F488: OFF | H488: EPOLIS_RAW
A489: EPOLIS_RAW | B489: 紫陽花 -AZISAI- | C489: A | D489: OFF | E489: MIRROR | F489: OFF | H489: EPOLIS_RAW
A490: EPOLIS_RAW | B490: アストライアの双皿 | C490: A | D490: FLIP | E490: MIRROR | F490: MIRROR | H490: EPOLIS_RAW
A491: EPOLIS_RAW | B491: 天邪鬼 | C491: A | D491: OFF | E491: MIRROR | F491: OFF | H491: EPOLIS_RAW
A492: EPOLIS_RAW | B492: イザナミノナゲキ | C492: A | D492: OFF | E492: MIRROR | F492: OFF | H492: EPOLIS_RAW
A493: EPOLIS_RAW | B493: 栄冠のカンパネラ | C493: A | D493: OFF | E493: MIRROR | F493: OFF | H493: EPOLIS_RAW
A494: EPOLIS_RAW | B494: ÆTHER | C494: L | D494: OFF | E494: MIRROR | F494: OFF | H494: EPOLIS_RAW
A495: EPOLIS_RAW | B495: 駅猫のワルツ | C495: A | D495: OFF | E495: MIRROR | F495: OFF | H495: EPOLIS_RAW
A496: EPOLIS_RAW | B496: ΕΛΠΙΣ | C496: A | D496: OFF | E496: MIRROR | F496: OFF | H496: EPOLIS_RAW
A497: EPOLIS_RAW | B497: ΕΛΠΙΣ | C497: L | D497: OFF | E497: MIRROR | F497: OFF | H497: EPOLIS_RAW
A498: EPOLIS_RAW | B498: 焔極OVERKILL | C498: A | D498: OFF | E498: MIRROR | F498: OFF | H498: EPOLIS_RAW
... A1179: XYZ012_RAW | B1179: Usual Days-remix | C1179: A | D1179: OFF | E1179: OFF | F1179: MIRROR | H1179: XYZ012_RAW
A1180: XYZ012_RAW | B1180: 255 | C1180: A | D1180: FLIP | E1180: MIRROR | F1180: MIRROR | H1180: XYZ012_RAW
A1181: XYZ012_RAW | B1181: シムルグの目醒め | C1181: A | D1181: FLIP | E1181: MIRROR | F1181: OFF | H1181: XYZ012_RAW
A1182: XYZ012_RAW | B1182: 神謳 -RESONANCE- | C1182: A | D1182: FLIP | E1182: MIRROR | F1182: MIRROR | H1182: XYZ012_RAW
A1183: XYZ012_RAW | B1183: パラドキシカル・タイムリープトライアル(Short Ver.) | C1183: A | D1183: OFF | E1183: MIRROR | F1183: OFF | H1183: XYZ012_RAW
A1184: XYZ012_RAW | B1184: Carmina | C1184: A | D1184: FLIP | E1184: MIRROR | F1184: MIRROR | H1184: XYZ012_RAW
A1185: XYZ012_RAW | B1185: Carry Me Away | C1185: A | D1185: OFF | E1185: MIRROR | F1185: OFF | H1185: XYZ012_RAW
A1186: XYZ012_RAW | B1186: CODE:Ø | C1186: A | D1186: OFF | E1186: MIRROR | F1186: OFF | H1186: XYZ012_RAW
A1187: XYZ012_RAW | B1187: COSMIC CYBER | C1187: A | D1187: OFF | E1187: MIRROR | F1187: OFF | H1187: XYZ012_RAW
A1188: XYZ012_RAW | B1188: dAuntl3ss | C1188: A | D1188: OFF | E1188: OFF | F1188: MIRROR | H1188: XYZ012_RAW
A1189: XYZ012_RAW | B1189: Dr. Chemical & Killing Machine | C1189: A | D1189: OFF | E1189: OFF | F1189: MIRROR | H1189: XYZ012_RAW
A1190: XYZ012_RAW | B1190: DRUNK MONKY | C1190: A | D1190: OFF | E1190: OFF | F1190: MIRROR | H1190: XYZ012_RAW
A1191: XYZ012_RAW | B1191: GENE | C1191: A | D1191: OFF | E1191: OFF | F1191: MIRROR | H1191: XYZ012_RAW
...

Sheet Sheet2
A1: DATA | B1: Version | C1: Title | D1: Difficulty | E1: Lv | F1: Lv.x | G1: comment
A2: ON | B2: [7th] | C2: A | D2: A | E2: 12 | F2: =_xlfn.XLOOKUP(C2&" ["&D2&"]",Sheet3!B:B,Sheet3!A:A,0) -> #NAME?
A3: ON | B3: [LC] | C3: A MINSTREL ～ ver.short-scape ～ | D3: L | E3: 12 | F3: =_xlfn.XLOOKUP(C3&" ["&D3&"]",Sheet3!B:B,Sheet3!A:A,0) -> #NAME?
A4: ON | B4: [RED] | C4: AA | D4: A | E4: 12 | F4: =_xlfn.XLOOKUP(C4&" ["&D4&"]",Sheet3!B:B,Sheet3!A:A,0) -> #NAME?
A5: ON | B5: [CAN] | C5: AA -rebuild- | D5: A | E5: 12 | F5: =_xlfn.XLOOKUP(C5&" ["&D5&"]",Sheet3!B:B,Sheet3!A:A,0) -> #NAME?
A6: ON | B6: [Cast] | C6: ABSOLUTE EVIL | D6: A | E6: 12 | F6: =_xlfn.XLOOKUP(C6&" ["&D6&"]",Sheet3!B:B,Sheet3!A:A,0) -> #NAME?
A7: ON | B7: [EPO] | C7: ACTØ | D7: A | E7: 12 | F7: =_xlfn.XLOOKUP(C7&" ["&D7&"]",Sheet3!B:B,Sheet3!A:A,0) -> #NAME?
A8: ON | B8: [SPA] | C8: Adularia | D8: A | E8: 12 | F8: =_xlfn.XLOOKUP(C8&" ["&D8&"]",Sheet3!B:B,Sheet3!A:A,0) -> #NAME?
A9: ON | B9: [Root] | C9: Afterimage d'automne | D9: A | E9: 12 | F9: =_xlfn.XLOOKUP(C9&" ["&D9&"]",Sheet3!B:B,Sheet3!A:A,0) -> #NAME?
A10: ON | B10: [Cast] | C10: Aftermath | D10: A | E10: 12 | F10: =_xlfn.XLOOKUP(C10&" ["&D10&"]",Sheet3!B:B,Sheet3!A:A,0) -> #NAME?
A11: ON | B11: [SIR] | C11: AIR RAID FROM THA UNDAGROUND | D11: L | E11: 12 | F11: =_xlfn.XLOOKUP(C11&" ["&D11&"]",Sheet3!B:B,Sheet3!A:A,0) -> #NAME?
A12: ON | B12: [HERO] | C12: AKASHIC BREAK | D12: A | E12: 12 | F12: =_xlfn.XLOOKUP(C12&" ["&D12&"]",Sheet3!B:B,Sheet3!A:A,0) -> #NAME?
A13: ON | B13: [SPA] | C13: ALBA -黎明- | D13: L | E13: 12 | F13: =_xlfn.XLOOKUP(C13&" ["&D13&"]",Sheet3!B:B,Sheet3!A:A,0) -> #NAME?
... A569: ON | B569: [PEN] | C569: ZZ | D569: A | E569: 12 | F569: =_xlfn.XLOOKUP(C569&" ["&D569&"]",Sheet3!B:B,Sheet3!A:A,0) -> #NAME?
A570: ON | B570: [Pink] | C570: 1116 | D570: A | E570: 12 | F570: =_xlfn.XLOOKUP(C570&" ["&D570&"]",Sheet3!B:B,Sheet3!A:A,0) -> #NAME?
A571: ON | B571: [cop] | C571: 199024club -Re:BounceKiller- | D571: A | E571: 12 | F571: =_xlfn.XLOOKUP(C571&" ["&D571&"]",Sheet3!B:B,Sheet3!A:A,0) -> #NAME?
A572: ON | B572: [10th] | C572: 1st Samurai | D572: A | E572: 12 | F572: =_xlfn.XLOOKUP(C572&" ["&D572&"]",Sheet3!B:B,Sheet3!A:A,0) -> #NAME?
A573: ON | B573: [SPS] | C573: 2 Be Continued | D573: A | E573: 12 | F573: =_xlfn.XLOOKUP(C573&" ["&D573&"]",Sheet3!B:B,Sheet3!A:A,0) -> #NAME?
A574: ON | B574: [Cast] | C574: 2 Beasts Unchained | D574: A | E574: 12 | F574: =_xlfn.XLOOKUP(C574&" ["&D574&"]",Sheet3!B:B,Sheet3!A:A,0) -> #NAME?
A575: ON | B575: [RESI] | C575: 24h Endurance Race | D575: A | E575: 12 | F575: =_xlfn.XLOOKUP(C575&" ["&D575&"]",Sheet3!B:B,Sheet3!A:A,0) -> #NAME?
A576: ON | B576: [CAN] | C576: 255 | D576: A | E576: 12 | F576: =_xlfn.XLOOKUP(C576&" ["&D576&"]",Sheet3!B:B,Sheet3!A:A,0) -> #NAME?
A577: ON | B577: [EMP] | C577: 3y3s | D577: A | E577: 12 | F577: =_xlfn.XLOOKUP(C577&" ["&D577&"]",Sheet3!B:B,Sheet3!A:A,0) -> #NAME?
A578: ON | B578: [RESI] | C578: [ ]DENTITY | D578: A | E578: 12 | F578: =_xlfn.XLOOKUP(C578&" ["&D578&"]",Sheet3!B:B,Sheet3!A:A,0) -> #NAME?
A579: ON | B579: [cop] | C579: 紫陽花 -AZISAI- | D579: A | E579: 12 | F579: =_xlfn.XLOOKUP(C579&" ["&D579&"]",Sheet3!B:B,Sheet3!A:A,0) -> #NAME?
A580: ON | B580: [cop] | C580: 紫陽花 -AZISAI- | D580: L | E580: 12 | F580: =_xlfn.XLOOKUP(C580&" ["&D580&"]",Sheet3!B:B,Sheet3!A:A,0) -> #NAME?
A581: ON | B581: [tri] | C581: アストライアの双皿 | D581: A | E581: 12 | F581: =_xlfn.XLOOKUP(C581&" ["&D581&"]",Sheet3!B:B,Sheet3!A:A,0) -> #NAME?
A582: ON | B582: [Cast] | C582: 天邪鬼 | D582: A | E582: 12 | F582: =_xlfn.XLOOKUP(C582&" ["&D582&"]",Sheet3!B:B,Sheet3!A:A,0) -> #NAME?
A583: ON | B583: [Pink] | C583: アラビアン ハイパー ナイト | D583: A | E583: 12 | F583: =_xlfn.XLOOKUP(C583&" ["&D583&"]",Sheet3!B:B,Sheet3!A:A,0) -> #NAME?
A584: ON | B584: [Pink] | C584: uәn | D584: A | E584: 12 | F584: =_xlfn.XLOOKUP(C584&" ["&D584&"]",Sheet3!B:B,Sheet3!A:A,0) -> #NAME?
A585: ON | B585: [SPS] | C585: ιgniЯRuina | D585: A | E585: 12 | F585: =_xlfn.XLOOKUP(C585&" ["&D585&"]",Sheet3!B:B,Sheet3!A:A,0) -> #NAME?
A586: ON | B586: [SINO] | C586: イザナミノナゲキ | D586: A | E586: 12 | F586: =_xlfn.XLOOKUP(C586&" ["&D586&"]",Sheet3!B:B,Sheet3!A:A,0) -> #NAME?
A587: ON | B587: [SPS] | C587: 色を喪った街 | D587: A | E587: 12 | F587: =_xlfn.XLOOKUP(C587&" ["&D587&"]",Sheet3!B:B,Sheet3!A:A,0) -> #NAME?
A588: ON | B588: [RESI] | C588: 栄冠のカンパネラ | D588: A | E588: 12 | F588: =_xlfn.XLOOKUP(C588&" ["&D588&"]",Sheet3!B:B,Sheet3!A:A,0) -> #NAME?
... A1447: ON | B1447: [RESI] | C1447: 惑星☆ロリポップ | D1447: A | E1447: 11 | F1447: =_xlfn.XLOOKUP(C1447&" ["&D1447&"]",Sheet3!B:B,Sheet3!A:A,0) -> #NAME?

Sheet Sheet3
A2: LV.x | B2: Title
A3: 11.6 | B3: op.31 叙情 [A]
A4: 11.6 | B4: Kailua [A]
A5: 11.6 | B5: The Onlyonez [A]
A6: 11.8 | B6: Colors (radio edit) [A]
A7: 11.8 | B7: Spica [A]
A8: 11.8 | B8: FAKE TIME [H]
A9: 11.8 | B9: RED ZONE [L]
A10: 11.8 | B10: MINT [A]
A11: 11.8 | B11: Candy Galy [A]
A12: 11.8 | B12: Fascination MAXX [A]
A13: 11.8 | B13: oratio [A]
A14: 11.8 | B14: Go Beyond!! [A]
... A30: 11.8 | B30: 灼熱 Lost Summer Dayz [A]
A31: 12.0 | B31: era(nostalmix) [H]
A32: 12.0 | B32: Summer Vacation(CU mix) [H]
A33: 12.0 | B33: route 80s [A]
A34: 12.0 | B34: stoic [A]
A35: 12.0 | B35: murmur twins [A]
A36: 12.0 | B36: GHOST REVIVAL [A]
A37: 12.0 | B37: SCREAM SQUAD [A]
A38: 12.0 | B38: Concertino in Blue [A]
A39: 12.0 | B39: Ganymede [A]
A40: 12.0 | B40: smile [A]
A41: 12.0 | B41: snow storm [A]
A42: 12.0 | B42: Anisakis -somatic mutation type "Forza"- [A]
... A89: 12.0 | B89: RALLY '25 [A]
A90: 12.1 | B90: era(nostalmix) [A]
A91: 12.1 | B91: era(step mix) [A]
A92: 12.1 | B92: starmine [A]
A93: 12.1 | B93: QQQ [H]
A94: 12.1 | B94: 革命 [H]
A95: 12.1 | B95: 桜 [A]
A96: 12.1 | B96: lower world [A]
A97: 12.1 | B97: 1st Samurai [A]
A98: 12.1 | B98: gigadelic [H]
A99: 12.1 | B99: BLOCKS [A]
A100: 12.1 | B100: POODLE [L]
A101: 12.1 | B101: 華蝶風雪 [A]
... A793: 10.7 | B793: IN BETWEEN [A]
...
